Workbook
Name Slicer_Item_Fat_Content: #N/A
Name Slicer_Item_Group: #N/A
Name Slicer_Outlet_Type: #N/A
Name Slicer_Visibility_Group: #N/A

Sheet Clean_SuperStore_Data
A1: Item_Identifier | B1: Item_Weight | C1: Item_Fat_Content | D1: Item_Visibility | E1: Item_Type | F1: Item_MRP | G1: Outlet_Identifier | H1: Outlet_Establishment_Year | I1: Outlet_Size | J1: Outlet_Location_Type | K1: Outlet_Type | L1: Item_Outlet_Sales | M1: Item_Group | N1: Visibility_Group | O1: Outlet_Tier+Outlet_Type | P1: Outlet_Sales_Persentage | S1: Vlookup | T1: OUT049 | U1: =VLOOKUP(T1,A:L,2) -> 4.56
A2: FDC02 | B2: 21.35 | C2: Low Fat | D2: 0.0691 | E2: Canned | F2: 259.928 | G2: OUT018 | H2: 2009 | I2: Medium | J2: Tier 3 | K2: Supermarket Type2 | L2: 6768.5228 | M2: Non-Perisable | N2: Low Visibilty | O2: =_xlfn.CONCAT(J2,"-", LEFT(K2,12)) -> Tier 3-Supermarket | P2: =L2/SUM(L:L) -> 0.00014142053 | S2: Xlookup | T2: OUT049 | U2: {=_xlfn.XLOOKUP(T2,G:G,A:C)} -> FDC02 | V2: 21.35 | W2: Low Fat
A3: FDC02 | B3: 21.35 | C3: Low Fat | D3: 0.1152 | E3: Canned | F3: 258.328 | G3: OUT010 | H3: 1998 | J3: Tier 3 | K3: Grocery Store | L3: 520.6556 | M3: Non-Perisable | N3: High Visibility | O3: =_xlfn.CONCAT(J3,"-", LEFT(K3,12)) -> Tier 3-Grocery Stor | P3: =L3/SUM(L:L) -> 1.0878503e-05 | S3: maxifs | T3: =_xlfn.MAXIFS(L:L,C:C,"Low Fat") -> 9779.9362
A4: FDC02 | B4: 21.35 | C4: Low Fat | D4: 0.0688 | E4: Canned | F4: 258.528 | G4: OUT035 | H4: 2004 | I4: Small | J4: Tier 2 | K4: Supermarket Type1 | L4: 5206.556 | M4: Non-Perisable | N4: Low Visibilty | O4: =_xlfn.CONCAT(J4,"-", LEFT(K4,12)) -> Tier 2-Supermarket | P4: =L4/SUM(L:L) -> 0.00010878503 | S4: Unique | T4: {=_xlfn.UNIQUE(E:E)} -> Item_Type
A5: FDC02 | B5: 21.35 | C5: Low Fat | D5: 0.0688 | E5: Canned | F5: 260.428 | G5: OUT013 | H5: 1987 | I5: High | J5: Tier 3 | K5: Supermarket Type1 | L5: 3644.5892 | M5: Non-Perisable | N5: Low Visibilty | O5: =_xlfn.CONCAT(J5,"-", LEFT(K5,12)) -> Tier 3-Supermarket | P5: =L5/SUM(L:L) -> 7.6149519e-05 | T5: Canned
A6: FDR07 | B6: 21.35 | C6: Low Fat | D6: 0.1301 | E6: Fruits and Vegetables | F6: 96.209 | G6: OUT010 | H6: 1998 | J6: Tier 3 | K6: Grocery Store | L6: 190.4188 | M6: Perisable | N6: High Visibility | O6: =_xlfn.CONCAT(J6,"-", LEFT(K6,12)) -> Tier 3-Grocery Stor | P6: =L6/SUM(L:L) -> 3.9785828e-06 | T6: Fruits and Vegetables
A7: FDC02 | B7: 21.35 | C7: Low Fat | D7: 0.0688 | E7: Canned | F7: 258.328 | G7: OUT046 | H7: 1997 | I7: Small | J7: Tier 1 | K7: Supermarket Type1 | L7: 7028.8506 | M7: Non-Perisable | N7: Low Visibilty | O7: =_xlfn.CONCAT(J7,"-", LEFT(K7,12)) -> Tier 1-Supermarket | P7: =L7/SUM(L:L) -> 0.00014685979 | T7: Snack Foods
A8: FDR07 | B8: 21.35 | C8: Low Fat | D8: 0.0781 | E8: Fruits and Vegetables | F8: 96.009 | G8: OUT018 | H8: 2009 | I8: Medium | J8: Tier 3 | K8: Supermarket Type2 | L8: 380.8376 | M8: Perisable | N8: Low Visibilty | O8: =_xlfn.CONCAT(J8,"-", LEFT(K8,12)) -> Tier 3-Supermarket | P8: =L8/SUM(L:L) -> 7.9571657e-06 | T8: Meat
A9: FDR07 | B9: 21.35 | C9: Low Fat | D9: 0.0782 | E9: Fruits and Vegetables | F9: 96.809 | G9: OUT017 | H9: 2007 | J9: Tier 2 | K9: Supermarket Type1 | L9: 1100.3641 | M9: Perisable | N9: Low Visibilty | O9: =_xlfn.CONCAT(J9,"-", LEFT(K9,12)) -> Tier 2-Supermarket | P9: =L9/SUM(L:L) -> 2.2990848e-05 | T9: Household
A10: FDR07 | B10: 21.35 | C10: Low Fat | D10: 0.0777 | E10: Fruits and Vegetables | F10: 97.009 | G10: OUT035 | H10: 2004 | I10: Small | J10: Tier 2 | K10: Supermarket Type1 | L10: 1139.9805 | M10: Perisable | N10: Low Visibilty | O10: =_xlfn.CONCAT(J10,"-", LEFT(K10,12)) -> Tier 2-Supermarket | P10: =L10/SUM(L:L) -> 2.3818587e-05 | T10: Health and Hygiene
A11: FDR07 | B11: 21.35 | C11: Low Fat | D11: 0.0777 | E11: Fruits and Vegetables | F11: 96.109 | G11: OUT046 | H11: 1997 | I11: Small | J11: Tier 1 | K11: Supermarket Type1 | L11: 1237.3959 | M11: Perisable | N11: Low Visibilty | O11: =_xlfn.CONCAT(J11,"-", LEFT(K11,12)) -> Tier 1-Supermarket | P11: =L11/SUM(L:L) -> 2.5853971e-05 | T11: Starchy Foods
A12: FDR07 | B12: 21.35 | C12: Low Fat | D12: 0.0777 | E12: Fruits and Vegetables | F12: 97.209 | G12: OUT013 | H12: 1987 | I12: High | J12: Tier 3 | K12: Supermarket Type1 | L12: 1189.4367 | M12: Perisable | N12: Low Visibilty | O12: =_xlfn.CONCAT(J12,"-", LEFT(K12,12)) -> Tier 3-Supermarket | P12: =L12/SUM(L:L) -> 2.4851918e-05 | T12: Breakfast
A13: FDC02 | B13: 21.35 | C13: Low Fat | D13: 0.069 | E13: Canned | F13: 261.128 | G13: OUT045 | H13: 2002 | J13: Tier 2 | K13: Supermarket Type1 | L13: 4013.9395 | M13: Non-Perisable | N13: Low Visibilty | O13: =_xlfn.CONCAT(J13,"-", LEFT(K13,12)) -> Tier 2-Supermarket | P13: =L13/SUM(L:L) -> 8.3866671e-05 | T13: Breads
A14: FDC02 | B14: 21.35 | C14: Low Fat | D14: 0.0692 | E14: Canned | F14: 258.828 | G14: OUT017 | H14: 2007 | J14: Tier 2 | K14: Supermarket Type1 | L14: 5841.3268 | M14: Non-Perisable | N14: Low Visibilty | O14: =_xlfn.CONCAT(J14,"-", LEFT(K14,12)) -> Tier 2-Supermarket | P14: =L14/SUM(L:L) -> 0.00012204784 | T14: Frozen Foods
A15: FDC02 | B15: 21.35 | C15: Low Fat | D15: 0.0689 | E15: Canned | F15: 259.628 | G15: OUT049 | H15: 1999 | I15: Medium | J15: Tier 1 | K15: Supermarket Type1 | L15: 3311.5025 | M15: Non-Perisable | N15: Low Visibilty | O15: =_xlfn.CONCAT(J15,"-", LEFT(K15,12)) -> Tier 1-Supermarket | P15: =L15/SUM(L:L) -> 6.9190054e-05 | T15: Baking Goods
A16: FDR07 | B16: 21.35 | C16: Low Fat | D16: 0.0779 | E16: Fruits and Vegetables | F16: 97.009 | G16: OUT049 | H16: 1999 | I16: Medium | J16: Tier 1 | K16: Supermarket Type1 | L16: 762.0579 | M16: Perisable | N16: Low Visibilty | O16: =_xlfn.CONCAT(J16,"-", LEFT(K16,12)) -> Tier 1-Supermarket | P16: =L16/SUM(L:L) -> 1.5922327e-05 | T16: Soft Drinks
A17: FDR07 | B17: 21.35 | C17: Low Fat | D17: 0.0779 | E17: Fruits and Vegetables | F17: 96.909 | G17: OUT045 | H17: 2002 | J17: Tier 2 | K17: Supermarket Type1 | L17: 937.4715 | M17: Perisable | N17: Low Visibilty | O17: =_xlfn.CONCAT(J17,"-", LEFT(K17,12)) -> Tier 2-Supermarket | P17: =L17/SUM(L:L) -> 1.9587394e-05 | T17: Seafood
A18: FDA45 | B18: 21.25 | C18: Low Fat | D18: 0.1554 | E18: Snack Foods | F18: 178.237 | G18: OUT035 | H18: 2004 | I18: Small | J18: Tier 2 | K18: Supermarket Type1 | L18: 529.311 | M18: Non-Perisable | N18: High Visibility | O18: =_xlfn.CONCAT(J18,"-", LEFT(K18,12)) -> Tier 2-Supermarket | P18: =L18/SUM(L:L) -> 1.1059347e-05 | T18: Dairy
A19: FDQ21 | B19: 21.25 | C19: Low Fat | D19: 0.0195 | E19: Snack Foods | F19: 120.876 | G19: OUT018 | H19: 2009 | I19: Medium | J19: Tier 3 | K19: Supermarket Type2 | L19: 3150.5656 | M19: Non-Perisable | N19: Low Visibilty | O19: =_xlfn.CONCAT(J19,"-", LEFT(K19,12)) -> Tier 3-Supermarket | P19: =L19/SUM(L:L) -> 6.5827461e-05 | T19: Others
A20: FDT03 | B20: 21.25 | C20: Low Fat | D20: 0.01 | E20: Meat | F20: 185.561 | G20: OUT035 | H20: 2004 | I20: Small | J20: Tier 2 | K20: Supermarket Type1 | L20: 3123.9336 | M20: Perisable | N20: Low Visibilty | O20: =_xlfn.CONCAT(J20,"-", LEFT(K20,12)) -> Tier 2-Supermarket | P20: =L20/SUM(L:L) -> 6.5271016e-05 | T20: Hard Drinks
A21: FDQ21 | B21: 21.25 | C21: Low Fat | D21: 0.0194 | E21: Snack Foods | F21: 120.876 | G21: OUT046 | H21: 1997 | I21: Small | J21: Tier 1 | K21: Supermarket Type1 | L21: 3150.5656 | M21: Non-Perisable | N21: Low Visibilty | O21: =_xlfn.CONCAT(J21,"-", LEFT(K21,12)) -> Tier 1-Supermarket | P21: =L21/SUM(L:L) -> 6.5827461e-05 | T21: 0
A22: FDT03 | B22: 21.25 | C22: Low Fat | D22: 0.01 | E22: Meat | F22: 181.761 | G22: OUT018 | H22: 2009 | I22: Medium | J22: Tier 3 | K22: Supermarket Type2 | L22: 1102.5648 | M22: Perisable | N22: Low Visibilty | O22: =_xlfn.CONCAT(J22,"-", LEFT(K22,12)) -> Tier 3-Supermarket | P22: =L22/SUM(L:L) -> 2.3036829e-05 | S22: LARGE | T22: =LARGE(B:B,10) -> 21.35
A23: FDT03 | B23: 21.25 | C23: Low Fat | D23: 0.0167 | E23: Meat | F23: 185.261 | G23: OUT010 | H23: 1998 | J23: Tier 3 | K23: Grocery Store | L23: 183.7608 | M23: Perisable | N23: Low Visibilty | O23: =_xlfn.CONCAT(J23,"-", LEFT(K23,12)) -> Tier 3-Grocery Stor | P23: =L23/SUM(L:L) -> 3.8394715e-06 | S23: small | T23: =SMALL(B:B,10) -> 4.59
A24: FDT03 | B24: 21.25 | C24: Low Fat | D24: 0.0101 | E24: Meat | F24: 183.161 | G24: OUT017 | H24: 2007 | J24: Tier 2 | K24: Supermarket Type1 | L24: 2756.412 | M24: Perisable | N24: Low Visibilty | O24: =_xlfn.CONCAT(J24,"-", LEFT(K24,12)) -> Tier 2-Supermarket | P24: =L24/SUM(L:L) -> 5.7592073e-05
A25: NCO42 | B25: 21.25 | C25: Low Fat | D25: 0.0247 | E25: Household | F25: 146.01 | G25: OUT035 | H25: 2004 | I25: Small | J25: Tier 2 | K25: Supermarket Type1 | L25: 2916.204 | M25: Household | N25: Low Visibilty | O25: =_xlfn.CONCAT(J25,"-", LEFT(K25,12)) -> Tier 2-Supermarket | P25: =L25/SUM(L:L) -> 6.0930744e-05
A26: FDT03 | B26: 21.25 | C26: Low Fat | D26: 0.01 | E26: Meat | F26: 184.661 | G26: OUT045 | H26: 2002 | J26: Tier 2 | K26: Supermarket Type1 | L26: 367.5216 | M26: Perisable | N26: Low Visibilty | O26: =_xlfn.CONCAT(J26,"-", LEFT(K26,12)) -> Tier 2-Supermarket | P26: =L26/SUM(L:L) -> 7.6789431e-06
A27: NCO42 | B27: 21.25 | C27: Low Fat | D27: 0.0247 | E27: Household | F27: 145.11 | G27: OUT045 | H27: 2002 | J27: Tier 2 | K27: Supermarket Type1 | L27: 1603.9122 | M27: Household | N27: Low Visibilty | O27: =_xlfn.CONCAT(J27,"-", LEFT(K27,12)) -> Tier 2-Supermarket | P27: =L27/SUM(L:L) -> 3.3511909e-05
A28: NCX17 | B28: 21.25 | C28: Low Fat | D28: 0.1142 | E28: Health and Hygiene | F28: 231.23 | G28: OUT017 | H28: 2007 | J28: Tier 2 | K28: Supermarket Type1 | L28: 3029.39 | M28: Household | N28: High Visibility | O28: =_xlfn.CONCAT(J28,"-", LEFT(K28,12)) -> Tier 2-Supermarket | P28: =L28/SUM(L:L) -> 6.3295636e-05
A29: FDA45 | B29: 21.25 | C29: Low Fat | D29: 0.1553 | E29: Snack Foods | F29: 175.737 | G29: OUT013 | H29: 1987 | I29: High | J29: Tier 3 | K29: Supermarket Type1 | L29: 2117.244 | M29: Non-Perisable | N29: High Visibility | O29: =_xlfn.CONCAT(J29,"-", LEFT(K29,12)) -> Tier 3-Supermarket | P29: =L29/SUM(L:L) -> 4.4237389e-05
A30: FDQ21 | B30: 21.25 | C30: low fat | D30: 0.0194 | E30: Snack Foods | F30: 119.376 | G30: OUT013 | H30: 1987 | I30: High | J30: Tier 3 | K30: Supermarket Type1 | L30: 3271.7412 | M30: Non-Perisable | N30: Low Visibilty | O30: =_xlfn.CONCAT(J30,"-", LEFT(K30,12)) -> Tier 3-Supermarket | P30: =L30/SUM(L:L) -> 6.8359287e-05
A31: FDA45 | B31: 21.25 | C31: Low Fat | D31: 0.1557 | E31: Snack Foods | F31: 177.637 | G31: OUT045 | H31: 2002 | J31: Tier 2 | K31: Supermarket Type1 | L31: 2999.429 | M31: Non-Perisable | N31: High Visibility | O31: =_xlfn.CONCAT(J31,"-", LEFT(K31,12)) -> Tier 2-Supermarket | P31: =L31/SUM(L:L) -> 6.2669635e-05
A32: FDT03 | B32: 21.25 | C32: Low Fat | D32: 0.01 | E32: Meat | F32: 182.361 | G32: OUT046 | H32: 1997 | I32: Small | J32: Tier 1 | K32: Supermarket Type1 | L32: 551.2824 | M32: Perisable | N32: Low Visibilty | O32: =_xlfn.CONCAT(J32,"-", LEFT(K32,12)) -> Tier 1-Supermarket | P32: =L32/SUM(L:L) -> 1.1518415e-05
A33: FDA45 | B33: 21.25 | C33: Low Fat | D33: 0.156 | E33: Snack Foods | F33: 177.337 | G33: OUT018 | H33: 2009 | I33: Medium | J33: Tier 3 | K33: Supermarket Type2 | L33: 2822.992 | M33: Non-Perisable | N33: High Visibility | O33: =_xlfn.CONCAT(J33,"-", LEFT(K33,12)) -> Tier 3-Supermarket | P33: =L33/SUM(L:L) -> 5.8983186e-05
A34: FDQ21 | B34: 21.25 | C34: Low Fat | D34: 0.0195 | E34: Snack Foods | F34: 120.476 | G34: OUT017 | H34: 2007 | J34: Tier 2 | K34: Supermarket Type1 | L34: 1938.8096 | M34: Non-Perisable | N34: Low Visibilty | O34: =_xlfn.CONCAT(J34,"-", LEFT(K34,12)) -> Tier 2-Supermarket | P34: =L34/SUM(L:L) -> 4.0509207e-05
A35: FDQ21 | B35: 21.25 | C35: Low Fat | D35: 0.0195 | E35: Snack Foods | F35: 120.876 | G35: OUT045 | H35: 2002 | J35: Tier 2 | K35: Supermarket Type1 | L35: 1575.2828 | M35: Non-Perisable | N35: Low Visibilty | O35: =_xlfn.CONCAT(J35,"-", LEFT(K35,12)) -> Tier 2-Supermarket | P35: =L35/SUM(L:L) -> 3.2913731e-05
A36: NCX17 | B36: 21.25 | C36: Low Fat | D36: 0.1138 | E36: Health and Hygiene | F36: 232.83 | G36: OUT045 | H36: 2002 | J36: Tier 2 | K36: Supermarket Type1 | L36: 1398.18 | M36: Household | N36: High Visibility | O36: =_xlfn.CONCAT(J36,"-", LEFT(K36,12)) -> Tier 2-Supermarket | P36: =L36/SUM(L:L) -> 2.921337e-05
A37: FDQ21 | B37: 21.25 | C37: Low Fat | D37: 0.0195 | E37: Snack Foods | F37: 120.876 | G37: OUT049 | H37: 1999 | I37: Medium | J37: Tier 1 | K37: Supermarket Type1 | L37: 1454.1072 | M37: Non-Perisable | N37: Low Visibilty | O37: =_xlfn.CONCAT(J37,"-", LEFT(K37,12)) -> Tier 1-Supermarket | P37: =L37/SUM(L:L) -> 3.0381905e-05
A38: NCX17 | B38: 21.25 | C38: Low Fat | D38: 0.1141 | E38: Health and Hygiene | F38: 233.03 | G38: OUT018 | H38: 2009 | I38: Medium | J38: Tier 3 | K38: Supermarket Type2 | L38: 5592.72 | M38: Household | N38: High Visibility | O38: =_xlfn.CONCAT(J38,"-", LEFT(K38,12)) -> Tier 3-Supermarket | P38: =L38/SUM(L:L) -> 0.00011685348
A39: NCO42 | B39: 21.25 | C39: Low Fat | D39: 0.0247 | E39: Household | F39: 144.11 | G39: OUT049 | H39: 1999 | I39: Medium | J39: Tier 1 | K39: Supermarket Type1 | L39: 1749.7224 | M39: Household | N39: Low Visibilty | O39: =_xlfn.CONCAT(J39,"-", LEFT(K39,12)) -> Tier 1-Supermarket | P39: =L39/SUM(L:L) -> 3.6558446e-05
A40: NCO42 | B40: 21.25 | C40: Low Fat | D40: 0.0248 | E40: Household | F40: 146.71 | G40: OUT018 | H40: 2009 | I40: Medium | J40: Tier 3 | K40: Supermarket Type2 | L40: 1603.9122 | M40: Household | N40: Low Visibilty | O40: =_xlfn.CONCAT(J40,"-", LEFT(K40,12)) -> Tier 3-Supermarket | P40: =L40/SUM(L:L) -> 3.3511909e-05
...

Sheet Data_Profil_Cedveli
A1: İtem_Outlet_Sales-e esasen max,min,avg,Count ve Countblank melumatlari
B3: max | C3: min | D3: avarage | E3: count | F3: countblank
B4: =MAX(Clean_SuperStore_Data!L2:L11766) -> 10256.649 | C4: =MIN(Clean_SuperStore_Data!L2:L11766) -> 33.29 | D4: =AVERAGE(Clean_SuperStore_Data!L2:L11766) -> 2034.04 | E4: =COUNT(Clean_SuperStore_Data!L2:L11766) -> 11765 | F4: =COUNTBLANK(Clean_SuperStore_Data!L2:L11766) -> 0

Sheet Pivot_Table
A3: Row Labels | B3: Count of Item_Identifier | E3: Sum of Item_Outlet_Sales | F3: Column Labels | K3: Sum of Item_Outlet_Sales | L3: Column Labels | Q3: Sum of Item_Outlet_Sales | R3: Column Labels
A4: Low Fat | B4: 7607 | E4: Row Labels | F4: Grocery Store | G4: Supermarket Type1 | H4: Supermarket Type2 | I4: Grand Total | K4: Row Labels | L4: High Visibility | M4: Low Visibilty | N4: Unknown | O4: Grand Total | Q4: Row Labels | R4: Drinks | S4: Household | T4: Non-Perisable | U4: Perisable | V4: Grand Total
A5: Regular | B5: 4158 | E5: Baking Goods | F5: 19271.941 | G5: 1439523.5 | H5: 202836.35 | I5: 1661631.8 | K5: Baking Goods | L5: 332050.4 | M5: 1215588.1 | N5: 113993.31 | O5: 1661631.8 | Q5: 1987 | R5: 263794.35 | S5: 571696.72 | T5: 1262860.8 | U5: 1320254 | V5: 3418605.8
A6: Grand Total | B6: 11765 | E6: Breads | F6: 12137.902 | G6: 610893.68 | H6: 93978.059 | I6: 717009.64 | K6: Breads | L6: 111296.34 | M6: 560606 | N6: 45107.301 | O6: 717009.64 | Q6: 1997 | R6: 228972.12 | S6: 558041.15 | T6: 1261338.4 | U6: 1322457.4 | V6: 3370809
E7: Breakfast | F7: 4862.1961 | G7: 250165.99 | H7: 40354.785 | I7: 295382.97 | K7: Breakfast | L7: 60794.375 | M7: 218086.26 | N7: 16502.334 | O7: 295382.97 | Q7: 1998 | R7: 21123.507 | S7: 57022.755 | T7: 105012.78 | U7: 115864.89 | V7: 299023.93
E8: Canned | F8: 18132.007 | G8: 1598218.7 | H8: 217047.86 | I8: 1833398.6 | K8: Canned | L8: 446471.67 | M8: 1264995.1 | N8: 121931.82 | O8: 1833398.6 | Q8: 1999 | R8: 259748.61 | S8: 630726.4 | T8: 1283531.1 | U8: 1321621.9 | V8: 3495627.9
E9: Dairy | F9: 23488.329 | G9: 1683131.5 | H9: 250559.56 | I9: 1957179.4 | K9: Dairy | L9: 381779.62 | M9: 1475124.3 | N9: 100275.49 | O9: 1957179.4 | Q9: 2002 | R9: 248619.98 | S9: 549990.67 | T9: 1188254.8 | U9: 1255175.2 | V9: 3242040.6
E10: Frozen Foods | F10: 29036.711 | G10: 1983296.6 | H10: 279709.35 | I10: 2292042.7 | K10: Frozen Foods | L10: 398920.08 | M10: 1757769.8 | N10: 135352.79 | O10: 2292042.7 | Q10: 2004 | R10: 257313.03 | S10: 622753.07 | T10: 1353204 | U10: 1373974.6 | V10: 3607244.7
E11: Fruits and Vegetables | F11: 41030.432 | G11: 3003982.8 | H11: 425698.66 | I11: 3470711.9 | K11: Fruits and Vegetables | L11: 757868.49 | M11: 2474453.8 | N11: 238389.61 | O11: 3470711.9 | Q11: 2007 | R11: 265770.89 | S11: 576064.65 | T11: 1320002.2 | U11: 1355703.6 | V11: 3517541.4
E12: Hard Drinks | F12: 6906.2977 | G12: 515144.19 | H12: 72699.142 | I12: 594749.63 | K12: Hard Drinks | L12: 104170.2 | M12: 452780.65 | N12: 37798.777 | O12: 594749.63 | Q12: 2009 | R12: 221442.15 | S12: 514469.73 | T12: 1088534.5 | U12: 1155140.9 | V12: 2979587.4
A13: Row Labels | B13: Sum of Item_Outlet_Sales | E13: Health and Hygiene | F13: 19231.715 | G13: 1176847.8 | H13: 174049.78 | I13: 1370129.3 | K13: Health and Hygiene | L13: 166468.91 | M13: 1122347.1 | N13: 81313.359 | O13: 1370129.3 | Q13: Grand Total | R13: 1766784.6 | S13: 4080765.1 | T13: 8862738.6 | U13: 9220192.4 | V13: 23930481
A14: High Visibility | B14: 4468409.5 | E14: Household | F14: 37791.04 | G14: 2332424.8 | H14: 340419.95 | I14: 2710635.8 | K14: Household | L14: 374980.81 | M14: 2170730.8 | N14: 164924.19 | O14: 2710635.8
A15: Low Visibilty | B15: 17937777 | E15: Meat | F15: 18988.853 | G15: 1062366.6 | H15: 155783.69 | I15: 1237139.1 | K15: Meat | L15: 165028.29 | M15: 982490.48 | N15: 89620.34 | O15: 1237139.1
A16: Unknown | B16: 1524294.2 | E16: Others | F16: 5704.3581 | G16: 379244.21 | H16: 57894.534 | I16: 442843.1 | K16: Others | L16: 61972.96 | M16: 344306.46 | N16: 36563.68 | O16: 442843.1
A17: Grand Total | B17: 23930481 | E17: Seafood | F17: 947.4334 | G17: 149288.5 | H17: 26284.627 | I17: 176520.56 | K17: Seafood | L17: 59745.436 | M17: 108146.35 | N17: 8628.768 | O17: 176520.56
E18: Snack Foods | F18: 41884.789 | G18: 3020906.5 | H18: 434897.65 | I18: 3497688.9 | K18: Snack Foods | L18: 741020.14 | M18: 2542115.1 | N18: 214553.65 | O18: 3497688.9
E19: Soft Drinks | F19: 14217.21 | G19: 1009074.8 | H19: 148743 | I19: 1172035 | K19: Soft Drinks | L19: 215120.27 | M19: 883398.2 | N19: 73516.518 | O19: 1172035
E20: Starchy Foods | F20: 5392.7179 | G20: 437359.26 | H20: 58630.366 | I20: 501382.35 | K20: Starchy Foods | L20: 90721.445 | M20: 364838.63 | N20: 45822.274 | O20: 501382.35
E21: Grand Total | F21: 299023.93 | G21: 20651870 | H21: 2979587.4 | I21: 23930481 | K21: Grand Total | L21: 4468409.5 | M21: 17937777 | N21: 1524294.2 | O21: 23930481
A23: Row Labels | B23: Sum of Item_Outlet_Sales | E23: Row Labels | F23: Sum of Item_Outlet_Sales | H23: Row Labels | I23: Sum of Item_Outlet_Sales | K23: Row Labels | L23: Sum of Item_Outlet_Sales | N23: Sum of Item_Outlet_Sales | O23: Column Labels
A24: High Visibility | B24: 4468409.5 | E24: High Visibility | H24: OUT010 | I24: 299023.93 | K24: Drinks | L24: 1766784.6 | N24: Row Labels | O24: Low Fat | P24: Regular | Q24: Grand Total
A25: Low Visibilty | B25: 17937777 | E25: OUT010 | F25: 138994.25 | H25: OUT013 | I25: 3418605.8 | K25: Household | L25: 4080765.1 | N25: Drinks | O25: 1618021.2 | P25: 148763.44 | Q25: 1766784.6
A26: Unknown | B26: 1524294.2 | E26: OUT013 | F26: 646693.22 | H26: OUT017 | I26: 3517541.4 | K26: Non-Perisable | L26: 8862738.6 | N26: Household | O26: 4080765.1 | Q26: 4080765.1
A27: Grand Total | B27: 23930481 | E27: OUT017 | F27: 614054.56 | H27: OUT018 | I27: 2979587.4 | K27: Perisable | L27: 9220192.4 | N27: Non-Perisable | O27: 5074776.2 | P27: 3787962.4 | Q27: 8862738.6
E28: OUT018 | F28: 576226.72 | H28: OUT035 | I28: 3607244.7 | N28: Perisable | O28: 4599726.5 | P28: 4620466 | Q28: 9220192.4
E29: OUT035 | F29: 638094.57 | H29: OUT045 | I29: 3242040.6 | N29: Grand Total | O29: 15373289 | P29: 8557191.8 | Q29: 23930481
E30: OUT045 | F30: 640790.44 | H30: OUT046 | I30: 3370809
E31: OUT046 | F31: 603615.82 | H31: OUT049 | I31: 3495627.9
E32: OUT049 | F32: 609939.87 | H32: Grand Total | I32: 23930481
E33: High Visibility Total | F33: 4468409.5
E34: Low Visibilty
E35: OUT010 | F35: 140634.85
E36: OUT013 | F36: 2553372.6
E37: OUT017 | F37: 2701473.7
E38: OUT018 | F38: 2194579.1
E39: OUT035 | F39: 2753813.7
E40: OUT045 | F40: 2388586.3
E41: OUT046 | F41: 2568834.8
E42: OUT049 | F42: 2636482.1
E43: Low Visibilty Total | F43: 17937777
...

Sheet Dashboard
